Internal Server Error: /books/88888
Traceback (most recent call last):
  File "C:\Users\malvi\Desktop\my_expirience\venv\lib\site-packages\django\core\handlers\exception.py", line 55, in inner
    response = get_response(request)
  File "C:\Users\malvi\Desktop\my_expirience\venv\lib\site-packages\django\core\handlers\base.py", line 197, in _get_response
    response = wrapped_callback(request, *callback_args, **callback_kwargs)
  File "C:\Users\malvi\Desktop\my_expirience\venv\lib\site-packages\django\views\generic\base.py", line 104, in view
    return self.dispatch(request, *args, **kwargs)
  File "C:\Users\malvi\Desktop\my_expirience\venv\lib\site-packages\django\views\generic\base.py", line 143, in dispatch
    return handler(request, *args, **kwargs)
  File "C:\Users\malvi\Desktop\my_expirience\books\views.py", line 12, in get
    book = Book.objects.get(id=kwargs['id'])
  File "C:\Users\malvi\Desktop\my_expirience\venv\lib\site-packages\django\db\models\manager.py", line 87, in manager_method
    return getattr(self.get_queryset(), name)(*args, **kwargs)
  File "C:\Users\malvi\Desktop\my_expirience\venv\lib\site-packages\django\db\models\query.py", line 649, in get
    raise self.model.DoesNotExist(
books.models.Book.DoesNotExist: Book matching query does not exist.
"GET /books/88888 HTTP/1.1" 500 87208
Internal Server Error: /authors/4/
Traceback (most recent call last):
  File "C:\Users\malvi\Desktop\my_expirience\venv\lib\site-packages\django\core\handlers\exception.py", line 55, in inner
    response = get_response(request)
  File "C:\Users\malvi\Desktop\my_expirience\venv\lib\site-packages\django\core\handlers\base.py", line 197, in _get_response
    response = wrapped_callback(request, *callback_args, **callback_kwargs)
  File "C:\Users\malvi\Desktop\my_expirience\venv\lib\site-packages\django\views\decorators\http.py", line 64, in inner
    return func(request, *args, **kwargs)
  File "C:\Users\malvi\Desktop\my_expirience\service\views.py", line 24, in author_show
    author_info = Author.objects.filter(Author, id=author_id)
  File "C:\Users\malvi\Desktop\my_expirience\venv\lib\site-packages\django\db\models\manager.py", line 87, in manager_method
    return getattr(self.get_queryset(), name)(*args, **kwargs)
  File "C:\Users\malvi\Desktop\my_expirience\venv\lib\site-packages\django\db\models\query.py", line 1476, in filter
    return self._filter_or_exclude(False, args, kwargs)
  File "C:\Users\malvi\Desktop\my_expirience\venv\lib\site-packages\django\db\models\query.py", line 1494, in _filter_or_exclude
    clone._filter_or_exclude_inplace(negate, args, kwargs)
  File "C:\Users\malvi\Desktop\my_expirience\venv\lib\site-packages\django\db\models\query.py", line 1501, in _filter_or_exclude_inplace
    self._query.add_q(Q(*args, **kwargs))
  File "C:\Users\malvi\Desktop\my_expirience\venv\lib\site-packages\django\db\models\sql\query.py", line 1613, in add_q
    clause, _ = self._add_q(q_object, self.used_aliases)
  File "C:\Users\malvi\Desktop\my_expirience\venv\lib\site-packages\django\db\models\sql\query.py", line 1645, in _add_q
    child_clause, needed_inner = self.build_filter(
  File "C:\Users\malvi\Desktop\my_expirience\venv\lib\site-packages\django\db\models\sql\query.py", line 1492, in build_filter
    arg, value = filter_expr
TypeError: cannot unpack non-iterable ModelBase object
"GET /authors/4/ HTTP/1.1" 500 107915
Internal Server Error: /656565/
Traceback (most recent call last):
  File "C:\Users\malvi\Desktop\my_expirience\venv\lib\site-packages\django\core\handlers\exception.py", line 55, in inner
    response = get_response(request)
  File "C:\Users\malvi\Desktop\my_expirience\venv\lib\site-packages\django\core\handlers\base.py", line 197, in _get_response
    response = wrapped_callback(request, *callback_args, **callback_kwargs)
  File "C:\Users\malvi\Desktop\my_expirience\venv\lib\site-packages\django\views\decorators\http.py", line 64, in inner
    return func(request, *args, **kwargs)
  File "C:\Users\malvi\Desktop\my_expirience\service\views.py", line 17, in show_info_genres
    genre_info = Genre.objects.get(id=genre_id)
  File "C:\Users\malvi\Desktop\my_expirience\venv\lib\site-packages\django\db\models\manager.py", line 87, in manager_method
    return getattr(self.get_queryset(), name)(*args, **kwargs)
  File "C:\Users\malvi\Desktop\my_expirience\venv\lib\site-packages\django\db\models\query.py", line 649, in get
    raise self.model.DoesNotExist(
books.models.Genre.DoesNotExist: Genre matching query does not exist.
"GET /656565/ HTTP/1.1" 500 81987
Internal Server Error: /56575/
Traceback (most recent call last):
  File "C:\Users\malvi\Desktop\my_expirience\venv\lib\site-packages\django\core\handlers\exception.py", line 55, in inner
    response = get_response(request)
  File "C:\Users\malvi\Desktop\my_expirience\venv\lib\site-packages\django\core\handlers\base.py", line 197, in _get_response
    response = wrapped_callback(request, *callback_args, **callback_kwargs)
  File "C:\Users\malvi\Desktop\my_expirience\venv\lib\site-packages\django\views\decorators\http.py", line 64, in inner
    return func(request, *args, **kwargs)
  File "C:\Users\malvi\Desktop\my_expirience\service\views.py", line 18, in show_info_genres
    if Genre.objects.get(id=genre_id):
  File "C:\Users\malvi\Desktop\my_expirience\venv\lib\site-packages\django\db\models\manager.py", line 87, in manager_method
    return getattr(self.get_queryset(), name)(*args, **kwargs)
  File "C:\Users\malvi\Desktop\my_expirience\venv\lib\site-packages\django\db\models\query.py", line 649, in get
    raise self.model.DoesNotExist(
books.models.Genre.DoesNotExist: Genre matching query does not exist.
"GET /56575/ HTTP/1.1" 500 82000
Internal Server Error: /comments/create/67564/
Traceback (most recent call last):
  File "C:\Users\malvi\Desktop\my_expirience\venv\lib\site-packages\django\core\handlers\exception.py", line 55, in inner
    response = get_response(request)
  File "C:\Users\malvi\Desktop\my_expirience\venv\lib\site-packages\django\core\handlers\base.py", line 197, in _get_response
    response = wrapped_callback(request, *callback_args, **callback_kwargs)
  File "C:\Users\malvi\Desktop\my_expirience\venv\lib\site-packages\django\views\generic\base.py", line 104, in view
    return self.dispatch(request, *args, **kwargs)
  File "C:\Users\malvi\Desktop\my_expirience\venv\lib\site-packages\django\views\generic\base.py", line 143, in dispatch
    return handler(request, *args, **kwargs)
  File "C:\Users\malvi\Desktop\my_expirience\comments\views.py", line 25, in post
    book = Book.objects.get(id=book_id)
  File "C:\Users\malvi\Desktop\my_expirience\venv\lib\site-packages\django\db\models\manager.py", line 87, in manager_method
    return getattr(self.get_queryset(), name)(*args, **kwargs)
  File "C:\Users\malvi\Desktop\my_expirience\venv\lib\site-packages\django\db\models\query.py", line 649, in get
    raise self.model.DoesNotExist(
books.models.Book.DoesNotExist: Book matching query does not exist.
"POST /comments/create/67564/ HTTP/1.1" 500 89667
Internal Server Error: /books/1
Traceback (most recent call last):
  File "C:\Users\malvi\Desktop\my_expirience\venv\lib\site-packages\django\core\handlers\exception.py", line 55, in inner
    response = get_response(request)
  File "C:\Users\malvi\Desktop\my_expirience\venv\lib\site-packages\django\core\handlers\base.py", line 197, in _get_response
    response = wrapped_callback(request, *callback_args, **callback_kwargs)
  File "C:\Users\malvi\Desktop\my_expirience\venv\lib\site-packages\django\views\generic\base.py", line 104, in view
    return self.dispatch(request, *args, **kwargs)
  File "C:\Users\malvi\Desktop\my_expirience\venv\lib\site-packages\django\views\generic\base.py", line 143, in dispatch
    return handler(request, *args, **kwargs)
  File "C:\Users\malvi\Desktop\my_expirience\books\views.py", line 20, in get
    return render(request, 'books/book.html', context={'book': book, 'comments': comments})
  File "C:\Users\malvi\Desktop\my_expirience\venv\lib\site-packages\django\shortcuts.py", line 25, in render
    content = loader.render_to_string(template_name, context, request, using=using)
  File "C:\Users\malvi\Desktop\my_expirience\venv\lib\site-packages\django\template\loader.py", line 62, in render_to_string
    return template.render(context, request)
  File "C:\Users\malvi\Desktop\my_expirience\venv\lib\site-packages\django\template\backends\django.py", line 61, in render
    return self.template.render(context)
  File "C:\Users\malvi\Desktop\my_expirience\venv\lib\site-packages\django\template\base.py", line 171, in render
    return self._render(context)
  File "C:\Users\malvi\Desktop\my_expirience\venv\lib\site-packages\django\template\base.py", line 163, in _render
    return self.nodelist.render(context)
  File "C:\Users\malvi\Desktop\my_expirience\venv\lib\site-packages\django\template\base.py", line 1000, in render
    return SafeString("".join([node.render_annotated(context) for node in self]))
  File "C:\Users\malvi\Desktop\my_expirience\venv\lib\site-packages\django\template\base.py", line 1000, in <listcomp>
    return SafeString("".join([node.render_annotated(context) for node in self]))
  File "C:\Users\malvi\Desktop\my_expirience\venv\lib\site-packages\django\template\base.py", line 961, in render_annotated
    return self.render(context)
  File "C:\Users\malvi\Desktop\my_expirience\venv\lib\site-packages\django\template\loader_tags.py", line 159, in render
    return compiled_parent._render(context)
  File "C:\Users\malvi\Desktop\my_expirience\venv\lib\site-packages\django\template\base.py", line 163, in _render
    return self.nodelist.render(context)
  File "C:\Users\malvi\Desktop\my_expirience\venv\lib\site-packages\django\template\base.py", line 1000, in render
    return SafeString("".join([node.render_annotated(context) for node in self]))
  File "C:\Users\malvi\Desktop\my_expirience\venv\lib\site-packages\django\template\base.py", line 1000, in <listcomp>
    return SafeString("".join([node.render_annotated(context) for node in self]))
  File "C:\Users\malvi\Desktop\my_expirience\venv\lib\site-packages\django\template\base.py", line 961, in render_annotated
    return self.render(context)
  File "C:\Users\malvi\Desktop\my_expirience\venv\lib\site-packages\django\template\loader_tags.py", line 65, in render
    result = block.nodelist.render(context)
  File "C:\Users\malvi\Desktop\my_expirience\venv\lib\site-packages\django\template\base.py", line 1000, in render
    return SafeString("".join([node.render_annotated(context) for node in self]))
  File "C:\Users\malvi\Desktop\my_expirience\venv\lib\site-packages\django\template\base.py", line 1000, in <listcomp>
    return SafeString("".join([node.render_annotated(context) for node in self]))
  File "C:\Users\malvi\Desktop\my_expirience\venv\lib\site-packages\django\template\base.py", line 961, in render_annotated
    return self.render(context)
  File "C:\Users\malvi\Desktop\my_expirience\venv\lib\site-packages\django\template\defaulttags.py", line 326, in render
    return nodelist.render(context)
  File "C:\Users\malvi\Desktop\my_expirience\venv\lib\site-packages\django\template\base.py", line 1000, in render
    return SafeString("".join([node.render_annotated(context) for node in self]))
  File "C:\Users\malvi\Desktop\my_expirience\venv\lib\site-packages\django\template\base.py", line 1000, in <listcomp>
    return SafeString("".join([node.render_annotated(context) for node in self]))
  File "C:\Users\malvi\Desktop\my_expirience\venv\lib\site-packages\django\template\base.py", line 961, in render_annotated
    return self.render(context)
  File "C:\Users\malvi\Desktop\my_expirience\venv\lib\site-packages\django\template\defaulttags.py", line 479, in render
    url = reverse(view_name, args=args, kwargs=kwargs, current_app=current_app)
  File "C:\Users\malvi\Desktop\my_expirience\venv\lib\site-packages\django\urls\base.py", line 88, in reverse
    return resolver._reverse_with_prefix(view, prefix, *args, **kwargs)
  File "C:\Users\malvi\Desktop\my_expirience\venv\lib\site-packages\django\urls\resolvers.py", line 851, in _reverse_with_prefix
    raise NoReverseMatch(msg)
django.urls.exceptions.NoReverseMatch: Reverse for 'comment_create' with arguments '(1,)' not found. 1 pattern(s) tried: ['comments/create/\\Z']
"GET /books/1 HTTP/1.1" 500 192324
Internal Server Error: /comments/create/
Traceback (most recent call last):
  File "C:\Users\malvi\Desktop\my_expirience\venv\lib\site-packages\django\core\handlers\exception.py", line 55, in inner
    response = get_response(request)
  File "C:\Users\malvi\Desktop\my_expirience\venv\lib\site-packages\django\core\handlers\base.py", line 197, in _get_response
    response = wrapped_callback(request, *callback_args, **callback_kwargs)
  File "C:\Users\malvi\Desktop\my_expirience\venv\lib\site-packages\django\views\generic\base.py", line 104, in view
    return self.dispatch(request, *args, **kwargs)
  File "C:\Users\malvi\Desktop\my_expirience\venv\lib\site-packages\django\views\generic\base.py", line 143, in dispatch
    return handler(request, *args, **kwargs)
  File "C:\Users\malvi\Desktop\my_expirience\comments\views.py", line 25, in post
    book = Book.objects.get(id=book_id)
  File "C:\Users\malvi\Desktop\my_expirience\venv\lib\site-packages\django\db\models\manager.py", line 87, in manager_method
    return getattr(self.get_queryset(), name)(*args, **kwargs)
  File "C:\Users\malvi\Desktop\my_expirience\venv\lib\site-packages\django\db\models\query.py", line 649, in get
    raise self.model.DoesNotExist(
books.models.Book.DoesNotExist: Book matching query does not exist.
"POST /comments/create/ HTTP/1.1" 500 89600
Internal Server Error: /comments/create/
Traceback (most recent call last):
  File "C:\Users\malvi\Desktop\my_expirience\venv\lib\site-packages\django\core\handlers\exception.py", line 55, in inner
    response = get_response(request)
  File "C:\Users\malvi\Desktop\my_expirience\venv\lib\site-packages\django\core\handlers\base.py", line 197, in _get_response
    response = wrapped_callback(request, *callback_args, **callback_kwargs)
  File "C:\Users\malvi\Desktop\my_expirience\venv\lib\site-packages\django\views\generic\base.py", line 104, in view
    return self.dispatch(request, *args, **kwargs)
  File "C:\Users\malvi\Desktop\my_expirience\venv\lib\site-packages\django\views\generic\base.py", line 143, in dispatch
    return handler(request, *args, **kwargs)
  File "C:\Users\malvi\Desktop\my_expirience\comments\views.py", line 30, in post
    return redirect('show_book', id=book_id)
  File "C:\Users\malvi\Desktop\my_expirience\venv\lib\site-packages\django\shortcuts.py", line 49, in redirect
    return redirect_class(resolve_url(to, *args, **kwargs))
  File "C:\Users\malvi\Desktop\my_expirience\venv\lib\site-packages\django\shortcuts.py", line 180, in resolve_url
    return reverse(to, args=args, kwargs=kwargs)
  File "C:\Users\malvi\Desktop\my_expirience\venv\lib\site-packages\django\urls\base.py", line 88, in reverse
    return resolver._reverse_with_prefix(view, prefix, *args, **kwargs)
  File "C:\Users\malvi\Desktop\my_expirience\venv\lib\site-packages\django\urls\resolvers.py", line 851, in _reverse_with_prefix
    raise NoReverseMatch(msg)
django.urls.exceptions.NoReverseMatch: Reverse for 'show_book' with keyword arguments '{'id': 1}' not found. 1 pattern(s) tried: ['books/(?P<book_id>[0-9]+)\\Z']
"POST /comments/create/ HTTP/1.1" 500 101437
Internal Server Error: /comments/create/
Traceback (most recent call last):
  File "C:\Users\malvi\Desktop\my_expirience\venv\lib\site-packages\django\core\handlers\exception.py", line 55, in inner
    response = get_response(request)
  File "C:\Users\malvi\Desktop\my_expirience\venv\lib\site-packages\django\core\handlers\base.py", line 197, in _get_response
    response = wrapped_callback(request, *callback_args, **callback_kwargs)
  File "C:\Users\malvi\Desktop\my_expirience\venv\lib\site-packages\django\views\generic\base.py", line 104, in view
    return self.dispatch(request, *args, **kwargs)
  File "C:\Users\malvi\Desktop\my_expirience\venv\lib\site-packages\django\views\generic\base.py", line 143, in dispatch
    return handler(request, *args, **kwargs)
  File "C:\Users\malvi\Desktop\my_expirience\comments\views.py", line 24, in post
    return redirect('show_book', id=book_id)
  File "C:\Users\malvi\Desktop\my_expirience\venv\lib\site-packages\django\shortcuts.py", line 49, in redirect
    return redirect_class(resolve_url(to, *args, **kwargs))
  File "C:\Users\malvi\Desktop\my_expirience\venv\lib\site-packages\django\shortcuts.py", line 180, in resolve_url
    return reverse(to, args=args, kwargs=kwargs)
  File "C:\Users\malvi\Desktop\my_expirience\venv\lib\site-packages\django\urls\base.py", line 88, in reverse
    return resolver._reverse_with_prefix(view, prefix, *args, **kwargs)
  File "C:\Users\malvi\Desktop\my_expirience\venv\lib\site-packages\django\urls\resolvers.py", line 851, in _reverse_with_prefix
    raise NoReverseMatch(msg)
django.urls.exceptions.NoReverseMatch: Reverse for 'show_book' with keyword arguments '{'id': 1}' not found. 1 pattern(s) tried: ['books/(?P<book_id>[0-9]+)\\Z']
"POST /comments/create/ HTTP/1.1" 500 101083
Internal Server Error: /comments/create/
Traceback (most recent call last):
  File "C:\Users\malvi\Desktop\my_expirience\venv\lib\site-packages\django\core\handlers\exception.py", line 55, in inner
    response = get_response(request)
  File "C:\Users\malvi\Desktop\my_expirience\venv\lib\site-packages\django\core\handlers\base.py", line 197, in _get_response
    response = wrapped_callback(request, *callback_args, **callback_kwargs)
  File "C:\Users\malvi\Desktop\my_expirience\venv\lib\site-packages\django\views\generic\base.py", line 104, in view
    return self.dispatch(request, *args, **kwargs)
  File "C:\Users\malvi\Desktop\my_expirience\venv\lib\site-packages\django\views\generic\base.py", line 143, in dispatch
    return handler(request, *args, **kwargs)
  File "C:\Users\malvi\Desktop\my_expirience\comments\views.py", line 24, in post
    return redirect('show_book')
  File "C:\Users\malvi\Desktop\my_expirience\venv\lib\site-packages\django\shortcuts.py", line 49, in redirect
    return redirect_class(resolve_url(to, *args, **kwargs))
  File "C:\Users\malvi\Desktop\my_expirience\venv\lib\site-packages\django\shortcuts.py", line 180, in resolve_url
    return reverse(to, args=args, kwargs=kwargs)
  File "C:\Users\malvi\Desktop\my_expirience\venv\lib\site-packages\django\urls\base.py", line 88, in reverse
    return resolver._reverse_with_prefix(view, prefix, *args, **kwargs)
  File "C:\Users\malvi\Desktop\my_expirience\venv\lib\site-packages\django\urls\resolvers.py", line 851, in _reverse_with_prefix
    raise NoReverseMatch(msg)
django.urls.exceptions.NoReverseMatch: Reverse for 'show_book' with no arguments not found. 1 pattern(s) tried: ['books/(?P<book_id>[0-9]+)\\Z']
"POST /comments/create/ HTTP/1.1" 500 101224
Internal Server Error: /books//book
Traceback (most recent call last):
  File "C:\Users\malvi\Desktop\my_expirience\venv\lib\site-packages\django\core\handlers\exception.py", line 55, in inner
    response = get_response(request)
  File "C:\Users\malvi\Desktop\my_expirience\venv\lib\site-packages\django\core\handlers\base.py", line 197, in _get_response
    response = wrapped_callback(request, *callback_args, **callback_kwargs)
  File "C:\Users\malvi\Desktop\my_expirience\venv\lib\site-packages\django\views\generic\base.py", line 104, in view
    return self.dispatch(request, *args, **kwargs)
  File "C:\Users\malvi\Desktop\my_expirience\venv\lib\site-packages\django\views\generic\base.py", line 143, in dispatch
    return handler(request, *args, **kwargs)
  File "C:\Users\malvi\Desktop\my_expirience\books\views.py", line 12, in get
    if Book.objects.filter(id=kwargs['book_id']):
KeyError: 'book_id'
"GET /books//book HTTP/1.1" 500 79243
Internal Server Error: /books/book
Traceback (most recent call last):
  File "C:\Users\malvi\Desktop\my_expirience\venv\lib\site-packages\django\core\handlers\exception.py", line 55, in inner
    response = get_response(request)
  File "C:\Users\malvi\Desktop\my_expirience\venv\lib\site-packages\django\core\handlers\base.py", line 197, in _get_response
    response = wrapped_callback(request, *callback_args, **callback_kwargs)
  File "C:\Users\malvi\Desktop\my_expirience\venv\lib\site-packages\django\views\generic\base.py", line 104, in view
    return self.dispatch(request, *args, **kwargs)
  File "C:\Users\malvi\Desktop\my_expirience\venv\lib\site-packages\django\views\generic\base.py", line 143, in dispatch
    return handler(request, *args, **kwargs)
  File "C:\Users\malvi\Desktop\my_expirience\books\views.py", line 12, in get
    if Book.objects.filter(id=kwargs['book_id']):
KeyError: 'book_id'
"GET /books/book HTTP/1.1" 500 79237
Internal Server Error: /account/
Traceback (most recent call last):
  File "C:\Users\malvi\Desktop\my_expirience\venv\lib\site-packages\django\core\handlers\exception.py", line 55, in inner
    response = get_response(request)
  File "C:\Users\malvi\Desktop\my_expirience\venv\lib\site-packages\django\core\handlers\base.py", line 197, in _get_response
    response = wrapped_callback(request, *callback_args, **callback_kwargs)
  File "C:\Users\malvi\Desktop\my_expirience\venv\lib\site-packages\django\contrib\auth\decorators.py", line 23, in _wrapper_view
    return view_func(request, *args, **kwargs)
  File "C:\Users\malvi\Desktop\my_expirience\account\views.py", line 29, in dashboard
    return render(request, 'account/dashboard.html', {'comments': user_comments})
  File "C:\Users\malvi\Desktop\my_expirience\venv\lib\site-packages\django\shortcuts.py", line 25, in render
    content = loader.render_to_string(template_name, context, request, using=using)
  File "C:\Users\malvi\Desktop\my_expirience\venv\lib\site-packages\django\template\loader.py", line 62, in render_to_string
    return template.render(context, request)
  File "C:\Users\malvi\Desktop\my_expirience\venv\lib\site-packages\django\template\backends\django.py", line 61, in render
    return self.template.render(context)
  File "C:\Users\malvi\Desktop\my_expirience\venv\lib\site-packages\django\template\base.py", line 171, in render
    return self._render(context)
  File "C:\Users\malvi\Desktop\my_expirience\venv\lib\site-packages\django\template\base.py", line 163, in _render
    return self.nodelist.render(context)
  File "C:\Users\malvi\Desktop\my_expirience\venv\lib\site-packages\django\template\base.py", line 1000, in render
    return SafeString("".join([node.render_annotated(context) for node in self]))
  File "C:\Users\malvi\Desktop\my_expirience\venv\lib\site-packages\django\template\base.py", line 1000, in <listcomp>
    return SafeString("".join([node.render_annotated(context) for node in self]))
  File "C:\Users\malvi\Desktop\my_expirience\venv\lib\site-packages\django\template\base.py", line 961, in render_annotated
    return self.render(context)
  File "C:\Users\malvi\Desktop\my_expirience\venv\lib\site-packages\django\template\loader_tags.py", line 159, in render
    return compiled_parent._render(context)
  File "C:\Users\malvi\Desktop\my_expirience\venv\lib\site-packages\django\template\base.py", line 163, in _render
    return self.nodelist.render(context)
  File "C:\Users\malvi\Desktop\my_expirience\venv\lib\site-packages\django\template\base.py", line 1000, in render
    return SafeString("".join([node.render_annotated(context) for node in self]))
  File "C:\Users\malvi\Desktop\my_expirience\venv\lib\site-packages\django\template\base.py", line 1000, in <listcomp>
    return SafeString("".join([node.render_annotated(context) for node in self]))
  File "C:\Users\malvi\Desktop\my_expirience\venv\lib\site-packages\django\template\base.py", line 961, in render_annotated
    return self.render(context)
  File "C:\Users\malvi\Desktop\my_expirience\venv\lib\site-packages\django\template\loader_tags.py", line 65, in render
    result = block.nodelist.render(context)
  File "C:\Users\malvi\Desktop\my_expirience\venv\lib\site-packages\django\template\base.py", line 1000, in render
    return SafeString("".join([node.render_annotated(context) for node in self]))
  File "C:\Users\malvi\Desktop\my_expirience\venv\lib\site-packages\django\template\base.py", line 1000, in <listcomp>
    return SafeString("".join([node.render_annotated(context) for node in self]))
  File "C:\Users\malvi\Desktop\my_expirience\venv\lib\site-packages\django\template\base.py", line 961, in render_annotated
    return self.render(context)
  File "C:\Users\malvi\Desktop\my_expirience\venv\lib\site-packages\django\template\defaulttags.py", line 242, in render
    nodelist.append(node.render_annotated(context))
  File "C:\Users\malvi\Desktop\my_expirience\venv\lib\site-packages\django\template\base.py", line 961, in render_annotated
    return self.render(context)
  File "C:\Users\malvi\Desktop\my_expirience\venv\lib\site-packages\django\template\defaulttags.py", line 479, in render
    url = reverse(view_name, args=args, kwargs=kwargs, current_app=current_app)
  File "C:\Users\malvi\Desktop\my_expirience\venv\lib\site-packages\django\urls\base.py", line 88, in reverse
    return resolver._reverse_with_prefix(view, prefix, *args, **kwargs)
  File "C:\Users\malvi\Desktop\my_expirience\venv\lib\site-packages\django\urls\resolvers.py", line 851, in _reverse_with_prefix
    raise NoReverseMatch(msg)
django.urls.exceptions.NoReverseMatch: Reverse for 'comment_update' with arguments '(14,)' not found. 1 pattern(s) tried: ['comments/edit/\\Z']
"GET /account/ HTTP/1.1" 500 180487
Internal Server Error: /books/2
Traceback (most recent call last):
  File "C:\Users\malvi\Desktop\my_expirience\venv\lib\site-packages\django\core\handlers\exception.py", line 55, in inner
    response = get_response(request)
  File "C:\Users\malvi\Desktop\my_expirience\venv\lib\site-packages\django\core\handlers\base.py", line 197, in _get_response
    response = wrapped_callback(request, *callback_args, **callback_kwargs)
  File "C:\Users\malvi\Desktop\my_expirience\venv\lib\site-packages\django\views\generic\base.py", line 104, in view
    return self.dispatch(request, *args, **kwargs)
  File "C:\Users\malvi\Desktop\my_expirience\venv\lib\site-packages\django\views\generic\base.py", line 143, in dispatch
    return handler(request, *args, **kwargs)
  File "C:\Users\malvi\Desktop\my_expirience\books\views.py", line 20, in get
    request.session['comment_id'] = current_user_comment.id
AttributeError: 'NoneType' object has no attribute 'id'
"GET /books/2 HTTP/1.1" 500 79654
Internal Server Error: /comments/edit/
Traceback (most recent call last):
  File "C:\Users\malvi\Desktop\my_expirience\venv\lib\site-packages\django\core\handlers\exception.py", line 55, in inner
    response = get_response(request)
  File "C:\Users\malvi\Desktop\my_expirience\venv\lib\site-packages\django\core\handlers\base.py", line 197, in _get_response
    response = wrapped_callback(request, *callback_args, **callback_kwargs)
  File "C:\Users\malvi\Desktop\my_expirience\venv\lib\site-packages\django\views\generic\base.py", line 104, in view
    return self.dispatch(request, *args, **kwargs)
  File "C:\Users\malvi\Desktop\my_expirience\venv\lib\site-packages\django\views\generic\base.py", line 143, in dispatch
    return handler(request, *args, **kwargs)
  File "C:\Users\malvi\Desktop\my_expirience\comments\views.py", line 38, in get
    comment_id = request.session['comment_id']
  File "C:\Users\malvi\Desktop\my_expirience\venv\lib\site-packages\django\contrib\sessions\backends\base.py", line 53, in __getitem__
    return self._session[key]
KeyError: 'comment_id'
"GET /comments/edit/ HTTP/1.1" 500 82503
Internal Server Error: /comments/edit/
Traceback (most recent call last):
  File "C:\Users\malvi\Desktop\my_expirience\venv\lib\site-packages\django\core\handlers\exception.py", line 55, in inner
    response = get_response(request)
  File "C:\Users\malvi\Desktop\my_expirience\venv\lib\site-packages\django\core\handlers\base.py", line 197, in _get_response
    response = wrapped_callback(request, *callback_args, **callback_kwargs)
  File "C:\Users\malvi\Desktop\my_expirience\venv\lib\site-packages\django\views\generic\base.py", line 104, in view
    return self.dispatch(request, *args, **kwargs)
  File "C:\Users\malvi\Desktop\my_expirience\venv\lib\site-packages\django\views\generic\base.py", line 143, in dispatch
    return handler(request, *args, **kwargs)
  File "C:\Users\malvi\Desktop\my_expirience\comments\views.py", line 38, in get
    comment_id = request.session['comment_id']
  File "C:\Users\malvi\Desktop\my_expirience\venv\lib\site-packages\django\contrib\sessions\backends\base.py", line 53, in __getitem__
    return self._session[key]
KeyError: 'comment_id'
"GET /comments/edit/ HTTP/1.1" 500 82503
Internal Server Error: /43iuwchjnm/
Traceback (most recent call last):
  File "C:\Users\malvi\Desktop\my_expirience\venv\lib\site-packages\django\core\handlers\exception.py", line 55, in inner
    response = get_response(request)
  File "C:\Users\malvi\Desktop\my_expirience\venv\lib\site-packages\django\core\handlers\base.py", line 197, in _get_response
    response = wrapped_callback(request, *callback_args, **callback_kwargs)
  File "C:\Users\malvi\Desktop\my_expirience\venv\lib\site-packages\django\views\decorators\http.py", line 64, in inner
    return func(request, *args, **kwargs)
TypeError: notshowauth() got an unexpected keyword argument 'genre_str'
"GET /43iuwchjnm/ HTTP/1.1" 500 69518
